Workbook

Sheet Assumptions
A1: COSTGRID — LLM TOKEN COST FORECAST MODEL
A2: Blue = input (change me). Black = formula. All prices blended $/M tokens at 3:1 input:output. Companion to the CostGrid dashboard.
A4: 1 · PRICE MODULE — tier price decays to a hardware floor
A5: Hardware floor ($/Mtok) | B5: 0.04 | G5: Source: Spheron GPU cost/token benchmark, Apr 2026 — electricity-only floor $0.02–0.15
B6: p 2023 | C6: p 2026 | D6: decline %/yr
A7: Frontier flagship | B7: 37.5 | C7: 10 | D7: 0.18 | G7: 2026: Opus 4.8 $5/$25 → $10.00; GPT-5.5 $5/$30 → $11.25. Decline: Du arXiv:2603.28576 — flagship tier resists decay
A8: Mid-tier | B8: 15 | C8: 5 | D8: 0.35 | G8: 2026: Sonnet 4.6 $3/$15 → $6.00; Gemini 3.1 Pro $2/$12 → $4.50
A9: Budget small | B9: 1 | C9: 0.55 | D9: 0.467 | G9: 2026: Gemini Flash-Lite $0.25/$1.50 → $0.56. Decline = Du economy half-life ~1.1 yr
A10: Open-weight commodity | B10: 2 | C10: 0.35 | D10: 0.467 | G10: 2026: DeepSeek V4 Flash $0.14/$0.28 → $0.175; V4-Pro → $0.54. Decline = economy half-life ~1.1 yr
A12: 2 · ROUTING MODULE — blended price vs. substitution share
A13: Routing overhead on open slice | B13: 0.15 | G13: evals, fallback, orchestration on the substituted slice
A14: Risk-penalty exponent N | B14: 8 | G14: convexity of misrouting cost: penalty = k·frontier·s^N
A15: Risk coefficient k — 2023 | B15: 0.55 | G15: exit-multiple impairment of misrouted high-stakes work
A16: Risk coefficient k — 2026 | B16: 0.46 | G16: calibrated so risk-adjusted optimum ≈ 83% in 2026
A17: Risk coefficient k — 2030 | B17: 0.26 | G17: falls as Western open ecosystem matures → optimum ≈ 90%
A19: 3 · VOLUME MODULE — tokens per customer interaction (logistic)
A20: Tokens/interaction — 2023 pattern | B20: 1000 | G20: single chat call
A21: Tokens/interaction — plateau | B21: 400000 | G21: multi-step agentic orchestration, net of caching/efficiency; OpenRouter: agents ≈15x tokens/request and multi-call
A22: Logistic slope | B22: 2 | G22: how fast the agentic pattern takes over
A23: Logistic midpoint (yrs after 2026) | B23: 0.3
A24: EY anchor — cost/interaction 2023 | B24: 0.04 | G24: Source: EY Total Cost of Agents (2026)
A25: EY anchor — cost/interaction 2026 | B25: 1.2 | G25: Source: EY Total Cost of Agents (2026)
A27: 4 · SPEND MODULE (Jevons)
A28: Enterprise GenAI spend 2023 ($B) | B28: 1.7 | G28: Source: Menlo Ventures, State of GenAI in the Enterprise, Dec 2025
A29: Enterprise GenAI spend 2024 ($B) | B29: 11.5 | G29: Menlo, ibid.
A30: Enterprise GenAI spend 2025 ($B) | B30: 37 | G30: Menlo, ibid.
A31: Volume growth ×/yr 2026→2030 | B31: 3 | C31: 2.3 | D31: 1.9 | E31: 1.6 | F31: 1.45 | G31: decaying adoption-driven growth; OpenRouter volume ×5 in 6 months (2026) supports the near-term rate
A33: 5 · SEAT-PRICING MODULE (2026–2030)
A34: Frontier seat price 2026 ($/mo) | B34: 200 | G34: OpenAI Pro anchor; Altman: 'losing money' on it (Jan 2025)
A35: Seat drift if subsidy continues (%/yr) | B35: 0.05 | G35: land-grab: gentle decline
A36: Repricing hump if subsidy unwinds | B36: 1 | C36: 1.25 | D36: 1.35 | E36: 1.15 | F36: 0.98 | G36: +25–35% near IPOs, then falls back as compute cheapens
A37: Blended cost-to-serve 2026 ($/mo) | B37: 110 | G37: illustrative
A38: Cost-to-serve decline (%/yr) | B38: 0.18 | G38: tracks frontier price decline
A40: 6 · EBITDA / EXIT MODULE
A41: AI run-cost today, frontier-default ($M) | B41: 4 | G41: illustrative mid-size portfolio company
A42: Substitution share applied | B42: 0.8 | G42: risk-adjusted routing decision
A43: Net saving on AI run-cost line | B43: 0.6 | G43: token line falls ~69% at s=0.80 (see Model!B44); net ~60% after hosting/observability overhead
A44: Exit multiple | B44: 12 | G44: EV/EBITDA

Sheet Model
A1: MODEL — all cells are formulas driven by the Assumptions sheet
A3: Year | B3: 2023 | C3: 2024 | D3: 2025 | E3: 2026 | F3: 2027 | G3: 2028 | H3: 2029 | I3: 2030
A5: PRICES ($/Mtok, blended 3:1)
A6: Frontier flagship | B6: =IF(B$3<2026,Assumptions!$B$7*(Assumptions!$C$7/Assumptions!$B$7)^((B$3-2023)/3),Assumptions!$B$5+(Assumptions!$C$7-Assumptions!$B$5)*(1-Assumptions!$D$7)^(B$3-2026)) -> 37.5 | C6: =IF(C$3<2026,Assumptions!$B$7*(Assumptions!$C$7/Assumptions!$B$7)^((C$3-2023)/3),Assumptions!$B$5+(Assumptions!$C$7-Assumptions!$B$5)*(1-Assumptions!$D$7)^(C$3-2026)) -> 24.137235 | D6: =IF(D$3<2026,Assumptions!$B$7*(Assumptions!$C$7/Assumptions!$B$7)^((D$3-2023)/3),Assumptions!$B$5+(Assumptions!$C$7-Assumptions!$B$5)*(1-Assumptions!$D$7)^(D$3-2026)) -> 15.536163 | E6: =IF(E$3<2026,Assumptions!$B$7*(Assumptions!$C$7/Assumptions!$B$7)^((E$3-2023)/3),Assumptions!$B$5+(Assumptions!$C$7-Assumptions!$B$5)*(1-Assumptions!$D$7)^(E$3-2026)) -> 10 | F6: =IF(F$3<2026,Assumptions!$B$7*(Assumptions!$C$7/Assumptions!$B$7)^((F$3-2023)/3),Assumptions!$B$5+(Assumptions!$C$7-Assumptions!$B$5)*(1-Assumptions!$D$7)^(F$3-2026)) -> 8.2072 | G6: =IF(G$3<2026,Assumptions!$B$7*(Assumptions!$C$7/Assumptions!$B$7)^((G$3-2023)/3),Assumptions!$B$5+(Assumptions!$C$7-Assumptions!$B$5)*(1-Assumptions!$D$7)^(G$3-2026)) -> 6.737104 | H6: =IF(H$3<2026,Assumptions!$B$7*(Assumptions!$C$7/Assumptions!$B$7)^((H$3-2023)/3),Assumptions!$B$5+(Assumptions!$C$7-Assumptions!$B$5)*(1-Assumptions!$D$7)^(H$3-2026)) -> 5.5316253 | I6: =IF(I$3<2026,Assumptions!$B$7*(Assumptions!$C$7/Assumptions!$B$7)^((I$3-2023)/3),Assumptions!$B$5+(Assumptions!$C$7-Assumptions!$B$5)*(1-Assumptions!$D$7)^(I$3-2026)) -> 4.5431327
A7: Mid-tier | B7: =IF(B$3<2026,Assumptions!$B$8*(Assumptions!$C$8/Assumptions!$B$8)^((B$3-2023)/3),Assumptions!$B$5+(Assumptions!$C$8-Assumptions!$B$5)*(1-Assumptions!$D$8)^(B$3-2026)) -> 15 | C7: =IF(C$3<2026,Assumptions!$B$8*(Assumptions!$C$8/Assumptions!$B$8)^((C$3-2023)/3),Assumptions!$B$5+(Assumptions!$C$8-Assumptions!$B$5)*(1-Assumptions!$D$8)^(C$3-2026)) -> 10.400419 | D7: =IF(D$3<2026,Assumptions!$B$8*(Assumptions!$C$8/Assumptions!$B$8)^((D$3-2023)/3),Assumptions!$B$5+(Assumptions!$C$8-Assumptions!$B$5)*(1-Assumptions!$D$8)^(D$3-2026)) -> 7.2112479 | E7: =IF(E$3<2026,Assumptions!$B$8*(Assumptions!$C$8/Assumptions!$B$8)^((E$3-2023)/3),Assumptions!$B$5+(Assumptions!$C$8-Assumptions!$B$5)*(1-Assumptions!$D$8)^(E$3-2026)) -> 5 | F7: =IF(F$3<2026,Assumptions!$B$8*(Assumptions!$C$8/Assumptions!$B$8)^((F$3-2023)/3),Assumptions!$B$5+(Assumptions!$C$8-Assumptions!$B$5)*(1-Assumptions!$D$8)^(F$3-2026)) -> 3.264 | G7: =IF(G$3<2026,Assumptions!$B$8*(Assumptions!$C$8/Assumptions!$B$8)^((G$3-2023)/3),Assumptions!$B$5+(Assumptions!$C$8-Assumptions!$B$5)*(1-Assumptions!$D$8)^(G$3-2026)) -> 2.1356 | H7: =IF(H$3<2026,Assumptions!$B$8*(Assumptions!$C$8/Assumptions!$B$8)^((H$3-2023)/3),Assumptions!$B$5+(Assumptions!$C$8-Assumptions!$B$5)*(1-Assumptions!$D$8)^(H$3-2026)) -> 1.40214 | I7: =IF(I$3<2026,Assumptions!$B$8*(Assumptions!$C$8/Assumptions!$B$8)^((I$3-2023)/3),Assumptions!$B$5+(Assumptions!$C$8-Assumptions!$B$5)*(1-Assumptions!$D$8)^(I$3-2026)) -> 0.925391
A8: Budget small | B8: =IF(B$3<2026,Assumptions!$B$9*(Assumptions!$C$9/Assumptions!$B$9)^((B$3-2023)/3),Assumptions!$B$5+(Assumptions!$C$9-Assumptions!$B$5)*(1-Assumptions!$D$9)^(B$3-2026)) -> 1 | C8: =IF(C$3<2026,Assumptions!$B$9*(Assumptions!$C$9/Assumptions!$B$9)^((C$3-2023)/3),Assumptions!$B$5+(Assumptions!$C$9-Assumptions!$B$5)*(1-Assumptions!$D$9)^(C$3-2026)) -> 0.81932127 | D8: =IF(D$3<2026,Assumptions!$B$9*(Assumptions!$C$9/Assumptions!$B$9)^((D$3-2023)/3),Assumptions!$B$5+(Assumptions!$C$9-Assumptions!$B$5)*(1-Assumptions!$D$9)^(D$3-2026)) -> 0.67128734 | E8: =IF(E$3<2026,Assumptions!$B$9*(Assumptions!$C$9/Assumptions!$B$9)^((E$3-2023)/3),Assumptions!$B$5+(Assumptions!$C$9-Assumptions!$B$5)*(1-Assumptions!$D$9)^(E$3-2026)) -> 0.55 | F8: =IF(F$3<2026,Assumptions!$B$9*(Assumptions!$C$9/Assumptions!$B$9)^((F$3-2023)/3),Assumptions!$B$5+(Assumptions!$C$9-Assumptions!$B$5)*(1-Assumptions!$D$9)^(F$3-2026)) -> 0.31183 | G8: =IF(G$3<2026,Assumptions!$B$9*(Assumptions!$C$9/Assumptions!$B$9)^((G$3-2023)/3),Assumptions!$B$5+(Assumptions!$C$9-Assumptions!$B$5)*(1-Assumptions!$D$9)^(G$3-2026)) -> 0.18488539 | H8: =IF(H$3<2026,Assumptions!$B$9*(Assumptions!$C$9/Assumptions!$B$9)^((H$3-2023)/3),Assumptions!$B$5+(Assumptions!$C$9-Assumptions!$B$5)*(1-Assumptions!$D$9)^(H$3-2026)) -> 0.11722391 | I8: =IF(I$3<2026,Assumptions!$B$9*(Assumptions!$C$9/Assumptions!$B$9)^((I$3-2023)/3),Assumptions!$B$5+(Assumptions!$C$9-Assumptions!$B$5)*(1-Assumptions!$D$9)^(I$3-2026)) -> 0.081160346
A9: Open-weight commodity | B9: =IF(B$3<2026,Assumptions!$B$10*(Assumptions!$C$10/Assumptions!$B$10)^((B$3-2023)/3),Assumptions!$B$5+(Assumptions!$C$10-Assumptions!$B$5)*(1-Assumptions!$D$10)^(B$3-2026)) -> 2 | C9: =IF(C$3<2026,Assumptions!$B$10*(Assumptions!$C$10/Assumptions!$B$10)^((C$3-2023)/3),Assumptions!$B$5+(Assumptions!$C$10-Assumptions!$B$5)*(1-Assumptions!$D$10)^(C$3-2026)) -> 1.1186889 | D9: =IF(D$3<2026,Assumptions!$B$10*(Assumptions!$C$10/Assumptions!$B$10)^((D$3-2023)/3),Assumptions!$B$5+(Assumptions!$C$10-Assumptions!$B$5)*(1-Assumptions!$D$10)^(D$3-2026)) -> 0.62573247 | E9: =IF(E$3<2026,Assumptions!$B$10*(Assumptions!$C$10/Assumptions!$B$10)^((E$3-2023)/3),Assumptions!$B$5+(Assumptions!$C$10-Assumptions!$B$5)*(1-Assumptions!$D$10)^(E$3-2026)) -> 0.35 | F9: =IF(F$3<2026,Assumptions!$B$10*(Assumptions!$C$10/Assumptions!$B$10)^((F$3-2023)/3),Assumptions!$B$5+(Assumptions!$C$10-Assumptions!$B$5)*(1-Assumptions!$D$10)^(F$3-2026)) -> 0.20523 | G9: =IF(G$3<2026,Assumptions!$B$10*(Assumptions!$C$10/Assumptions!$B$10)^((G$3-2023)/3),Assumptions!$B$5+(Assumptions!$C$10-Assumptions!$B$5)*(1-Assumptions!$D$10)^(G$3-2026)) -> 0.12806759 | H9: =IF(H$3<2026,Assumptions!$B$10*(Assumptions!$C$10/Assumptions!$B$10)^((H$3-2023)/3),Assumptions!$B$5+(Assumptions!$C$10-Assumptions!$B$5)*(1-Assumptions!$D$10)^(H$3-2026)) -> 0.086940025 | I9: =IF(I$3<2026,Assumptions!$B$10*(Assumptions!$C$10/Assumptions!$B$10)^((I$3-2023)/3),Assumptions!$B$5+(Assumptions!$C$10-Assumptions!$B$5)*(1-Assumptions!$D$10)^(I$3-2026)) -> 0.065019034
A10: Frontier — convergence scenario | B10: =IF(B$3<2026,B6,Assumptions!$B$5+(Assumptions!$C$7-Assumptions!$B$5)*(1-Assumptions!$D$10)^(B$3-2026)) -> 37.5 | C10: =IF(C$3<2026,C6,Assumptions!$B$5+(Assumptions!$C$7-Assumptions!$B$5)*(1-Assumptions!$D$10)^(C$3-2026)) -> 24.137235 | D10: =IF(D$3<2026,D6,Assumptions!$B$5+(Assumptions!$C$7-Assumptions!$B$5)*(1-Assumptions!$D$10)^(D$3-2026)) -> 15.536163 | E10: =IF(E$3<2026,E6,Assumptions!$B$5+(Assumptions!$C$7-Assumptions!$B$5)*(1-Assumptions!$D$10)^(E$3-2026)) -> 10 | F10: =IF(F$3<2026,F6,Assumptions!$B$5+(Assumptions!$C$7-Assumptions!$B$5)*(1-Assumptions!$D$10)^(F$3-2026)) -> 5.34868 | G10: =IF(G$3<2026,G6,Assumptions!$B$5+(Assumptions!$C$7-Assumptions!$B$5)*(1-Assumptions!$D$10)^(G$3-2026)) -> 2.8695264 | H10: =IF(H$3<2026,H6,Assumptions!$B$5+(Assumptions!$C$7-Assumptions!$B$5)*(1-Assumptions!$D$10)^(H$3-2026)) -> 1.5481376 | I10: =IF(I$3<2026,I6,Assumptions!$B$5+(Assumptions!$C$7-Assumptions!$B$5)*(1-Assumptions!$D$10)^(I$3-2026)) -> 0.84383734 | K10: post-2026 frontier competed at the economy decline rate
A12: ROUTING (substitution share s → blended effective price)
A13: Risk coefficient k (interpolated) | B13: =IF(B$3<=2026,Assumptions!$B$15+(Assumptions!$B$16-Assumptions!$B$15)*(B$3-2023)/3,Assumptions!$B$16+(Assumptions!$B$17-Assumptions!$B$16)*(B$3-2026)/4) -> 0.55 | C13: =IF(C$3<=2026,Assumptions!$B$15+(Assumptions!$B$16-Assumptions!$B$15)*(C$3-2023)/3,Assumptions!$B$16+(Assumptions!$B$17-Assumptions!$B$16)*(C$3-2026)/4) -> 0.52 | D13: =IF(D$3<=2026,Assumptions!$B$15+(Assumptions!$B$16-Assumptions!$B$15)*(D$3-2023)/3,Assumptions!$B$16+(Assumptions!$B$17-Assumptions!$B$16)*(D$3-2026)/4) -> 0.49 | E13: =IF(E$3<=2026,Assumptions!$B$15+(Assumptions!$B$16-Assumptions!$B$15)*(E$3-2023)/3,Assumptions!$B$16+(Assumptions!$B$17-Assumptions!$B$16)*(E$3-2026)/4) -> 0.46 | F13: =IF(F$3<=2026,Assumptions!$B$15+(Assumptions!$B$16-Assumptions!$B$15)*(F$3-2023)/3,Assumptions!$B$16+(Assumptions!$B$17-Assumptions!$B$16)*(F$3-2026)/4) -> 0.41 | G13: =IF(G$3<=2026,Assumptions!$B$15+(Assumptions!$B$16-Assumptions!$B$15)*(G$3-2023)/3,Assumptions!$B$16+(Assumptions!$B$17-Assumptions!$B$16)*(G$3-2026)/4) -> 0.36 | H13: =IF(H$3<=2026,Assumptions!$B$15+(Assumptions!$B$16-Assumptions!$B$15)*(H$3-2023)/3,Assumptions!$B$16+(Assumptions!$B$17-Assumptions!$B$16)*(H$3-2026)/4) -> 0.31 | I13: =IF(I$3<=2026,Assumptions!$B$15+(Assumptions!$B$16-Assumptions!$B$15)*(I$3-2023)/3,Assumptions!$B$16+(Assumptions!$B$17-Assumptions!$B$16)*(I$3-2026)/4) -> 0.26
A14: Optimum substitution share s* | B14: =MIN(0.99,((B6-B9*(1+Assumptions!$B$13))/(B13*B6*Assumptions!$B$14))^(1/(Assumptions!$B$14-1))) -> 0.8019573 | C14: =MIN(0.99,((C6-C9*(1+Assumptions!$B$13))/(C13*C6*Assumptions!$B$14))^(1/(Assumptions!$B$14-1))) -> 0.8093939 | D14: =MIN(0.99,((D6-D9*(1+Assumptions!$B$13))/(D13*D6*Assumptions!$B$14))^(1/(Assumptions!$B$14-1))) -> 0.81715144 | E14: =MIN(0.99,((E6-E9*(1+Assumptions!$B$13))/(E13*E6*Assumptions!$B$14))^(1/(Assumptions!$B$14-1))) -> 0.82530743 | F14: =MIN(0.99,((F6-F9*(1+Assumptions!$B$13))/(F13*F6*Assumptions!$B$14))^(1/(Assumptions!$B$14-1))) -> 0.84041431 | G14: =MIN(0.99,((G6-G9*(1+Assumptions!$B$13))/(G13*G6*Assumptions!$B$14))^(1/(Assumptions!$B$14-1))) -> 0.85704016 | H14: =MIN(0.99,((H6-H9*(1+Assumptions!$B$13))/(H13*H6*Assumptions!$B$14))^(1/(Assumptions!$B$14-1))) -> 0.87602828 | I14: =MIN(0.99,((I6-I9*(1+Assumptions!$B$13))/(I13*I6*Assumptions!$B$14))^(1/(Assumptions!$B$14-1))) -> 0.89853042 | K14: s* = ((f − o(1+ov)) / (k·f·N))^(1/(N−1)) — first-order condition
A15: Blended price at optimum | B15: =B14*B9*(1+Assumptions!$B$13)+(1-B14)*B6+B13*B6*B14^Assumptions!$B$14 -> 12.799715 | C15: =C14*C9*(1+Assumptions!$B$13)+(1-C14)*C6+C13*C6*C14^Assumptions!$B$14 -> 7.9538897 | D15: =D14*D9*(1+Assumptions!$B$13)+(1-D14)*D6+D13*D6*D14^Assumptions!$B$14 -> 4.9422036 | E15: =E14*E9*(1+Assumptions!$B$13)+(1-E14)*E6+E13*E6*E14^Assumptions!$B$14 -> 3.0692229 | F15: =F14*F9*(1+Assumptions!$B$13)+(1-F14)*F6+F13*F6*F14^Assumptions!$B$14 -> 2.345489 | G15: =G14*G9*(1+Assumptions!$B$13)+(1-G14)*G6+G13*G6*G14^Assumptions!$B$14 -> 1.7953264 | H15: =H14*H9*(1+Assumptions!$B$13)+(1-H14)*H6+H13*H6*H14^Assumptions!$B$14 -> 1.3681356 | I15: =I14*I9*(1+Assumptions!$B$13)+(1-I14)*I6+I13*I6*I14^Assumptions!$B$14 -> 1.0300444
A16: Realized substitution share (input) | B16: 0.05 | C16: 0.08 | D16: 0.12 | E16: 0.15 | F16: 0.22 | G16: 0.3 | H16: 0.37 | I16: 0.45 | K16: what firms actually route — Menlo: measured open usage ~11–13% (2025); maturing FinOps closes the gap
A17: Blended effective price (realized) | B17: =B16*B9*(1+Assumptions!$B$13)+(1-B16)*B6+B13*B6*B16^Assumptions!$B$14 -> 35.74 | C17: =C16*C9*(1+Assumptions!$B$13)+(1-C16)*C6+C13*C6*C16^Assumptions!$B$14 -> 22.309175 | D17: =D16*D9*(1+Assumptions!$B$13)+(1-D16)*D6+D13*D6*D16^Assumptions!$B$14 -> 13.758174 | E17: =E16*E9*(1+Assumptions!$B$13)+(1-E16)*E6+E13*E6*E16^Assumptions!$B$14 -> 8.5603762 | F17: =F16*F9*(1+Assumptions!$B$13)+(1-F16)*F6+F13*F6*F16^Assumptions!$B$14 -> 6.4535577 | G17: =G16*G9*(1+Assumptions!$B$13)+(1-G16)*G6+G13*G6*G16^Assumptions!$B$14 -> 4.7603152 | H17: =H16*H9*(1+Assumptions!$B$13)+(1-H16)*H6+H13*H6*H16^Assumptions!$B$14 -> 3.5225192 | I17: =I16*I9*(1+Assumptions!$B$13)+(1-I16)*I6+I13*I6*I16^Assumptions!$B$14 -> 2.5343566
A19: VOLUME (tokens per customer interaction)
A20: Raw logistic (pattern shift) | B20: =Assumptions!$B$20+(Assumptions!$B$21-Assumptions!$B$20)/(1+EXP(-Assumptions!$B$22*((B$3-2026)-Assumptions!$B$23))) -> 1542.0495 | C20: =Assumptions!$B$20+(Assumptions!$B$21-Assumptions!$B$20)/(1+EXP(-Assumptions!$B$22*((C$3-2026)-Assumptions!$B$23))) -> 4970.7689 | D20: =Assumptions!$B$20+(Assumptions!$B$21-Assumptions!$B$20)/(1+EXP(-Assumptions!$B$22*((D$3-2026)-Assumptions!$B$23))) -> 28586.23 | E20: =Assumptions!$B$20+(Assumptions!$B$21-Assumptions!$B$20)/(1+EXP(-Assumptions!$B$22*((E$3-2026)-Assumptions!$B$23))) -> 142383.13 | F20: =Assumptions!$B$20+(Assumptions!$B$21-Assumptions!$B$20)/(1+EXP(-Assumptions!$B$22*((F$3-2026)-Assumptions!$B$23))) -> 321071.37 | G20: =Assumptions!$B$20+(Assumptions!$B$21-Assumptions!$B$20)/(1+EXP(-Assumptions!$B$22*((G$3-2026)-Assumptions!$B$23))) -> 387114.11 | H20: =Assumptions!$B$20+(Assumptions!$B$21-Assumptions!$B$20)/(1+EXP(-Assumptions!$B$22*((H$3-2026)-Assumptions!$B$23))) -> 398205.99 | I20: =Assumptions!$B$20+(Assumptions!$B$21-Assumptions!$B$20)/(1+EXP(-Assumptions!$B$22*((I$3-2026)-Assumptions!$B$23))) -> 399756.26
A21: Tokens implied by EY anchors | B21: =Assumptions!$B$24/B17*1000000 -> 1119.1942 | C21: ="" | D21: ="" | E21: =Assumptions!$B$25/E17*1000000 -> 140180.76 | F21: ="" | G21: ="" | H21: ="" | I21: ="" | K21: 2023 and 2026 pin the curve to EY $0.04 / $1.20
A22: Tokens per interaction (calibrated) | B22: =$B$21+($E$21-$B$21)/($E$20-$B$20)*(B20-$B$20) -> 1119.1942 | C22: =$B$21+($E$21-$B$21)/($E$20-$B$20)*(C20-$B$20) -> 4504.5919 | D22: =$B$21+($E$21-$B$21)/($E$20-$B$20)*(D20-$B$20) -> 27821.672 | E22: =$B$21+($E$21-$B$21)/($E$20-$B$20)*(E20-$B$20) -> 140180.76 | F22: =$B$21+($E$21-$B$21)/($E$20-$B$20)*(F20-$B$20) -> 316611.27 | G22: =$B$21+($E$21-$B$21)/($E$20-$B$20)*(G20-$B$20) -> 381819.56 | H22: =$B$21+($E$21-$B$21)/($E$20-$B$20)*(H20-$B$20) -> 392771.29 | I22: =$B$21+($E$21-$B$21)/($E$20-$B$20)*(I20-$B$20) -> 394301.98 | K22: raw logistic linearly mapped through the two EY anchors
A24: COST PER TASK / INTERACTION ($)
A25: At realized routing | B25: =B22/1000000*B17 -> 0.04 | C25: =C22/1000000*C17 -> 0.10049373 | D25: =D22/1000000*D17 -> 0.38277542 | E25: =E22/1000000*E17 -> 1.2 | F25: =F22/1000000*F17 -> 2.0432691 | G25: =G22/1000000*G17 -> 1.8175815 | H25: =H22/1000000*H17 -> 1.3835444 | I25: =I22/1000000*I17 -> 0.99930181
A26: At optimum routing | B26: =B22/1000000*B15 -> 0.014325367 | C26: =C22/1000000*C15 -> 0.035829027 | D26: =D22/1000000*D15 -> 0.13750037 | E26: =E22/1000000*E15 -> 0.43024599 | F26: =F22/1000000*F15 -> 0.74260825 | G26: =G22/1000000*G15 -> 0.68549075 | H26: =H22/1000000*H15 -> 0.53736437 | I26: =I22/1000000*I15 -> 0.40614853 | K26: the Agentic-FinOps prize: the gap between these two rows
A28: SPEND (Jevons: price × volume)
A29: Volume index (Mtok, implied) | B29: =Assumptions!$B$28/B17*1000 -> 47.565753 | C29: =Assumptions!$B$29/C17*1000 -> 515.48297 | D29: =Assumptions!$B$30/D17*1000 -> 2689.3103 | E29: =D29*Assumptions!$B$31 -> 8067.9309 | F29: =E29*Assumptions!$C$31 -> 18556.241 | G29: =F29*Assumptions!$D$31 -> 35256.858 | H29: =G29*Assumptions!$E$31 -> 56410.973 | I29: =H29*Assumptions!$F$31 -> 81795.91 | K29: 2023–25 backed out of Menlo actuals; 2026–30 grown at decaying rates
A30: Enterprise GenAI spend ($B) | B30: =B29*B17/1000 -> 1.7 | C30: =C29*C17/1000 -> 11.5 | D30: =D29*D17/1000 -> 37 | E30: =E29*E17/1000 -> 69.064523 | F30: =F29*F17/1000 -> 119.75377 | G30: =G29*G17/1000 -> 167.83376 | H30: =H29*H17/1000 -> 198.70874 | I30: =I29*I17/1000 -> 207.3
A32: KEY OUTPUTS
A33: Frontier / open gap — 2026 | B33: =E6/E9 -> 28.571429
A34: Frontier / open gap — 2030 (bifurcate) | B34: =I6/I9 -> 69.873889
A35: Frontier / open gap — 2030 (converge) | B35: =I10/I9 -> 12.978313
A36: Token index 2030 (2023 = 1) | B36: =I22/B22 -> 352.30882
A37: Peak cost per interaction ($) | B37: =MAX(B25:I25) -> 2.0432691
A38: EY check 2023 (must equal $0.04) | B38: =B25 -> 0.04
A39: EY check 2026 (must equal $1.20) | B39: =E25 -> 1.2
A41: SEAT PRICING ($/frontier-reasoning seat/mo, 2026–2030)
A42: Year | B42: 2026 | C42: 2027 | D42: 2028 | E42: 2029 | F42: 2030
A43: If subsidy continues | B43: =Assumptions!$B$34*(1-Assumptions!$B$35)^0 -> 200 | C43: =Assumptions!$B$34*(1-Assumptions!$B$35)^1 -> 190 | D43: =Assumptions!$B$34*(1-Assumptions!$B$35)^2 -> 180.5 | E43: =Assumptions!$B$34*(1-Assumptions!$B$35)^3 -> 171.475 | F43: =Assumptions!$B$34*(1-Assumptions!$B$35)^4 -> 162.90125
A44: If subsidy unwinds (hump) | B44: =Assumptions!$B$34*Assumptions!$B$36 -> 200 | C44: =Assumptions!$B$34*Assumptions!$C$36 -> 250 | D44: =Assumptions!$B$34*Assumptions!$D$36 -> 270 | E44: =Assumptions!$B$34*Assumptions!$E$36 -> 230 | F44: =Assumptions!$B$34*Assumptions!$F$36 -> 196
A45: Blended cost-to-serve floor | B45: =Assumptions!$B$37*(1-Assumptions!$B$38)^0 -> 110 | C45: =Assumptions!$B$37*(1-Assumptions!$B$38)^1 -> 90.2 | D45: =Assumptions!$B$37*(1-Assumptions!$B$38)^2 -> 73.964 | E45: =Assumptions!$B$37*(1-Assumptions!$B$38)^3 -> 60.65048 | F45: =Assumptions!$B$37*(1-Assumptions!$B$38)^4 -> 49.733394
A47: EBITDA / EXIT BRIDGE ($M)
A48: Token-line ratio at chosen s (2026) | B48: =(Assumptions!$B$42*E9*(1+Assumptions!$B$13)+(1-Assumptions!$B$42)*E6+E13*E6*Assumptions!$B$42^Assumptions!$B$14)/E6 -> 0.30937519
A49: AI run-cost now | B49: =Assumptions!$B$41 -> 4
...
